Workbook

Sheet Sheet1
A1: আয় | B1: আয় | C1: চাঁদ | D1: মামা | L1: মামা
A2: টিপ | B2: দিয়ে | C2: যা | L2: যা
A3: চাঁদের | B3: কপালে | C3: চাঁদ | L3: চাঁদ
A4: টিপ | B4: দিয়ে | C4: যা | L4: যা
A5: ধান | B5: ভানলে | C5: কুঁড়ো | D5: দেব | L5: দেব
A6: মাছ | B6: কাটলে | C6: মুড়ো | D6: দেব | L6: দেব
A7: কাল | B7: গাইয়ের | C7: দুধ | D7: দেব | L7: দেব
A8: দুধ | B8: খাবার | C8: বাটি | D8: দেব | L8: দেব
A9: চাঁদের | B9: কপালে | C9: চাঁদ | L9: চাঁদ
A10: টিপ | B10: দিয়ে | C10: যা | L10: যা
A11: আয়রে | B11: আয় | C11: টিয়ে | L11: টিয়ে
A12: নায়ে | B12: ভরা | C12: দিয়ে | L12: দিয়ে
A13: না | B13: নিয়ে | C13: গেল | D13: বোয়াল | E13: মাছে | L13: মাছ | M13: এ
A14: তাই | B14: না | C14: দেখে | D14: ভোদড় | E14: নাচে | L14: নাচ | M14: এ
A15: ওরে | B15: ভোদড় | C15: ফিরে | D15: চা | L15: চা
A16: খোকার | B16: নাচন | C16: দেখে | D16: যা | L16: যা
A17: নোটন | B17: নোটন | C17: পায়রা | D17: গুলি | L17: গুলি
A18: ঝোটন | B18: বেঁধেছে | L18: বেঁধে | M18: ছে | N18: ছি | O18: ছিলাম | P18: ছিনু | Q18: ছো | R18: ছিলে
A19: ওপারেতে | B19: ছেলে | C19: মেয়ে | L19: মেয়ে
A20: নাইতে | B20: নেমেছে | L20: নেমে | M20: ছে | N20: ছি | O20: ছিলাম | P20: ছিনু | Q20: ছো | R20: ছিলে
A21: দুই | B21: ধারে | C21: দুই | D21: রুই | E21: কাতলা | L21: কাতলা
A22: ভেসে | B22: উঠেছে | L22: উঠে | M22: ছে | N22: ছি | O22: ছিলাম | P22: ছো | Q22: ছিলে
A23: কে | B23: দেখেছে | C23: কে | D23: দেখেছে | L23: দেখে
A24: দাদা | B24: দেখেছে | L24: দেখে | M24: ছে | N24: ছি | O24: ছিলাম | P24: ছো | Q24: ছিলে
A25: দাদার | B25: হাতে | C25: কলম | D25: ছিল | L25: ছিল
A26: ছুঁড়ে | B26: মেরেছে | L26: মেরে | M26: ছে | N26: ছি | O26: ছিলাম | P26: ছো | Q26: ছিলে
A27: উঃ | B27: বড্ড | C27: লেগেছে | L27: লেগে | M27: ছে | N27: ছি | O27: ছিলাম | P27: ছো | Q27: ছিলে
A28: খোকা | B28: ঘুমাল | C28: পাড়া | D28: জুড়াল | L28: জুড়াল
A29: খোকা | B29: ঘুমাল | C29: পাড়া | D29: জুড়াল | E29: বর্গী | F29: এল | G29: দেশে | L29: দেশ | M29: এ
A30: বুলবুলিতে | B30: ধান | C30: খেয়েছে | D30: খাজনা | E30: দেব | F30: কিসে | L30: কি | M30: সে | N30: ভাবে
A31: ধান | B31: ফুরাল | C31: পান | D31: ফুরাল | E31: খাজনার | F31: উপায় | G31: কী | L31: কী
A32: আর | B32: কটা | C32: দিন | D32: সবুর | E32: কর | F32: রসুন | G32: বুনেছি | L32: বুন | M32: এছি | N32: লো | O32: ও | P32: ই
A33: বৃষ্টি | B33: পড়ে | C33: টাপুর | D33: টুপুর | L33: টুপুর
A34: বৃষ্টি | B34: পড়ে | C34: টাপুর | D34: টুপুর | E34: নদে | F34: এল | G34: বান | L34: বান
A35: শিব | B35: ঠাকুরের | C35: বিয়ে | D35: হল | E35: তিন | F35: কন্যা | G35: দান | L35: দান
A36: এক | B36: কন্যা | C36: রাঁধেন | D36: বাড়েন | E36: এক | F36: কন্যা | G36: খান | L36: খান
A37: এক | B37: কন্যা | C37: রাগ | D37: করে | E37: বাপের | F37: বাড়ি | G37: যান | L37: যান
A38: মোদের | B38: গরব | C38: মোদের | D38: আশা | E38: আ | F38: মরি | G38: বাংলা | H38: ভাষা | L38: ভাষা
A39: তোমার | B39: কোলে | C39: তোমার | D39: বোলে | E39: কতই | F39: শান্তি | G39: ভাল | H39: বাসা | K39: বেস | L39: বাস | M39: আ | N39: ই | O39: এছি
A40: কি | B40: যাদু | C40: বাংলা | D40: গানে | E40: গান | F40: গেয়ে | G40: দাঁড় | H40: মাঝি | I40: টানে | K40: টেন | L40: টান | M40: এ | N40: ই | O40: এছি
...

Sheet Sheet8
A1: অতি | C1: {=_xlfn.UNIQUE(A:A, FALSE,FALSE)} -> অতি | D1: =COUNTIF(A:A,C1) -> 1
A2: অনেক | C2: অনেক | D2: =COUNTIF(A:A,C2) -> 1
A3: অন্তর | C3: অন্তর | D3: =COUNTIF(A:A,C3) -> 1
A4: অন্ধকার | C4: অন্ধকার | D4: =COUNTIF(A:A,C4) -> 3
A5: অন্ধকারে | C5: অন্ধকারে | D5: =COUNTIF(A:A,C5) -> 1
A6: অন্ধকার | C6: অন্ন | D6: =COUNTIF(A:A,C6) -> 1
A7: অন্ধকার | C7: অপর | D7: =COUNTIF(A:A,C7) -> 2
A8: অন্ন | C8: আঁক | D8: =COUNTIF(A:A,C8) -> 1
A9: অপর | C9: আঁতকে | D9: =COUNTIF(A:A,C9) -> 1
A10: অপর | C10: আকাশ | D10: =COUNTIF(A:A,C10) -> 6
A11: আঁক | C11: আগ | D11: =COUNTIF(A:A,C11) -> 5
A12: আঁতকে | C12: আছ | D12: =COUNTIF(A:A,C12) -> 6
A13: আকাশ | C13: আজ | D13: =COUNTIF(A:A,C13) -> 1
... A710: তীরে | C710: হোথা | D710: =COUNTIF(A:A,C710) -> 1
A711: তুমি | C711: 0 | D711: =COUNTIF(A:A,C711) -> 0
A712: তুমি | D712: =COUNTIF(A:A,C712) -> 0
A713: তুমি | D713: =COUNTIF(A:A,C713) -> 0
A714: তুমি | D714: =COUNTIF(A:A,C714) -> 0
A715: তুমি | D715: =COUNTIF(A:A,C715) -> 0
A716: তুমি | D716: =COUNTIF(A:A,C716) -> 0
A717: তুমি | D717: =COUNTIF(A:A,C717) -> 0
A718: তুমি | D718: =COUNTIF(A:A,C718) -> 0
A719: তৃণলতা | D719: =COUNTIF(A:A,C719) -> 0
A720: তেজ | D720: =COUNTIF(A:A,C720) -> 0
A721: তেড় | D721: =COUNTIF(A:A,C721) -> 0
A722: তেড় | D722: =COUNTIF(A:A,C722) -> 0
A723: তেতো | D723: =COUNTIF(A:A,C723) -> 0
... A1015: পান | D1015: =COUNTIF(A:A,C1015) -> 0
A1016: পান
A1017: পান
A1018: পান
A1019: পাব
A1020: পাব
A1021: পায়রা
A1022: পা
A1023: পা
A1024: পা
A1025: পারুল
A1026: পালকি
A1027: পালকি
...

Sheet Sheet9
A1: না | B1: 27 | C1: 2 | D1: =COUNTIF(Sheet8!C1:C710, A1) -> 1
A2: যা | B2: 29 | C2: 4 | D2: =COUNTIF(Sheet8!C2:C711, A2) -> 1
A3: কর | B3: 28 | C3: 4 | D3: =COUNTIF(Sheet8!C3:C712, A3) -> 1
A4: বল | B4: 25 | C4: 4 | D4: =COUNTIF(Sheet8!C4:C713, A4) -> 1
A5: তার | B5: 17 | C5: 2 | D5: =COUNTIF(Sheet8!C5:C714, A5) -> 1
A6: মন | B6: 13 | C6: 2 | D6: =COUNTIF(Sheet8!C6:C715, A6) -> 1
A7: সে | B7: 13 | C7: 2 | D7: =COUNTIF(Sheet8!C7:C716, A7) -> 1
A8: আর | B8: 12 | C8: 1 | D8: =COUNTIF(Sheet8!C8:C717, A8) -> 1
A9: আস | B9: 9 | C9: 1 | D9: =COUNTIF(Sheet8!C9:C718, A9) -> 1
A10: চল | B10: 8 | C10: 1 | D10: =COUNTIF(Sheet8!C10:C719, A10) -> 1
A11: দে | B11: 8 | C11: 1 | D11: =COUNTIF(Sheet8!C11:C720, A11) -> 1
A12: ভাল | B12: 8 | C12: 1 | D12: =COUNTIF(Sheet8!C12:C721, A12) -> 1
A13: যে | B13: 36 | C13: =ROUND(B13/5,0) -> 7 | D13: =COUNTIF(Sheet8!C13:C722, A13) -> 1
A14: আম | B14: 35 | C14: =ROUND(B14/5,0) -> 7 | D14: =COUNTIF(Sheet8!C14:C723, A14) -> 1
A15: এক | B15: 18 | C15: =ROUND(B15/5,0) -> 4 | D15: =COUNTIF(Sheet8!C15:C724, A15) -> 1
A16: দেখ | B16: 17 | C16: =ROUND(B16/5,0) -> 3 | D16: =COUNTIF(Sheet8!C16:C725, A16) -> 1
A17: দি | B17: 16 | C17: =ROUND(B17/5,0) -> 3 | D17: =COUNTIF(Sheet8!C17:C726, A17) -> 1
A18: মা | B18: 15 | C18: =ROUND(B18/5,0) -> 3 | D18: =COUNTIF(Sheet8!C18:C727, A18) -> 1
A19: হয় | B19: 14 | C19: =ROUND(B19/5,0) -> 3 | D19: =COUNTIF(Sheet8!C19:C728, A19) -> 1
A20: ঘুম | B20: 11 | C20: =ROUND(B20/5,0) -> 2 | D20: =COUNTIF(Sheet8!C20:C729, A20) -> 1
A21: কোথা | B21: 10 | C21: =ROUND(B21/5,0) -> 2 | D21: =COUNTIF(Sheet8!C21:C730, A21) -> 1
A22: দিন | B22: 9 | C22: =ROUND(B22/5,0) -> 2 | D22: =COUNTIF(Sheet8!C22:C731, A22) -> 1
A23: তোমা | B23: 9 | C23: =ROUND(B23/5,0) -> 2 | D23: =COUNTIF(Sheet8!C23:C732, A23) -> 1
A24: নাহি | B24: 9 | C24: =ROUND(B24/5,0) -> 2 | D24: =COUNTIF(Sheet8!C24:C733, A24) -> 1
... A671: হোথা | B671: 1 | C671: =ROUND(B671/5,0) -> 0 | D671: =COUNTIF(Sheet8!C671:C1380, A671) -> 1

Sheet endings
A1: আকাশ | B1: এ | J1: =COUNTIF(A:A,#REF!) -> 0
A2: আকাশ | B2: এ | I2: {=_xlfn.UNIQUE(A:A, FALSE, FALSE)} -> আকাশ | J2: =COUNTIF(A:A,I2) -> 2
A3: আড়েই | B3: ই | I3: আড়েই | J3: =COUNTIF(A:A,I3) -> 1
A4: আবার | I4: আবার | J4: =COUNTIF(A:A,I4) -> 1
A5: আমা | B5: দের | C5: র | I5: আমা | J5: =COUNTIF(A:A,I5) -> 2
A6: আমা | B6: দের | C6: র | I6: আমি | J6: =COUNTIF(A:A,I6) -> 1
A7: আমি | I7: আয় | J7: =COUNTIF(A:A,I7) -> 1
A8: আয় | I8: আর | J8: =COUNTIF(A:A,I8) -> 2
A9: আর | I9: আরবার | J9: =COUNTIF(A:A,I9) -> 1
A10: আর | I10: আলো | J10: =COUNTIF(A:A,I10) -> 3
A11: আরবার | I11: আস | J11: =COUNTIF(A:A,I11) -> 2
A12: আলো | I12: আহরণ | J12: =COUNTIF(A:A,I12) -> 1
A13: আলো | I13: উঠ | J13: =COUNTIF(A:A,I13) -> 1
A14: আলো | I14: উৎপাত | J14: =COUNTIF(A:A,I14) -> 1
A15: আস | B15: আ | C15: এ | D15: বে | E15: বে | I15: উনিশ | J15: =COUNTIF(A:A,I15) -> 1
A16: আস | B16: আ | C16: এ | D16: ছে | E16: ছে | I16: উপদেশ | J16: =COUNTIF(A:A,I16) -> 1
A17: আহরণ | B17: এ | D17: আ | E17: এ | I17: এই | J17: =COUNTIF(A:A,I17) -> 1
A18: উঠ | B18: ছে | C18: ছি | D18: ছিলাম | E18: ছো | F18: ছি | I18: এক | J18: =COUNTIF(A:A,I18) -> 1
A19: উৎপাত | I19: এখান | J19: =COUNTIF(A:A,I19) -> 1
A20: উনিশ | B20: এ | I20: এড় | J20: =COUNTIF(A:A,I20) -> 1
A21: উপদেশ | B21: এ | I21: এর | J21: =COUNTIF(A:A,I21) -> 1
A22: এই | I22: ও | J22: =COUNTIF(A:A,I22) -> 2
A23: এক | B23: আ | I23: ওই | J23: =COUNTIF(A:A,I23) -> 1
A24: এখান | B24: এ | I24: ওঠা | J24: =COUNTIF(A:A,I24) -> 1
A25: এড় | B25: ইয়ে | C25: ইয়েছে | D25: আয় | E25: আলো | I25: ওর | J25: =COUNTIF(A:A,I25) -> 1
A26: এর | I26: কই | J26: =COUNTIF(A:A,I26) -> 1
A27: ও | I27: কথা | J27: =COUNTIF(A:A,I27) -> 1
A28: ও | I28: কম্প | J28: =COUNTIF(A:A,I28) -> 1
A29: ওই | I29: কর | J29: =COUNTIF(A:A,I29) -> 5
A30: ওঠা | I30: কলরব | J30: =COUNTIF(A:A,I30) -> 1
A31: ওর | B31: এ | I31: কাঁটা | J31: =COUNTIF(A:A,I31) -> 1
A32: কই | I32: কাটা | J32: =COUNTIF(A:A,I32) -> 1
A33: কথা | I33: কাতলা | J33: =COUNTIF(A:A,I33) -> 1
A34: কম্প | I34: কাপড় | J34: =COUNTIF(A:A,I34) -> 1
A35: কর | B35: এ | I35: কাবার | J35: =COUNTIF(A:A,I35) -> 1
A36: কর | B36: ও | I36: কালো | J36: =COUNTIF(A:A,I36) -> 1
A37: কর | B37: এ | I37: কি | J37: =COUNTIF(A:A,I37) -> 1
A38: কর | B38: এ | I38: কিল | J38: =COUNTIF(A:A,I38) -> 1
A39: কর | B39: এ | I39: কী | J39: =COUNTIF(A:A,I39) -> 1
A40: কলরব | I40: কুকুর | J40: =COUNTIF(A:A,I40) -> 1
...

Sheet endingbase
A1: না | B1: 9
A2: যা | B2: 8
A3: চল | B3: 6
A4: কর | B4: 5
A5: তার | B5: 5
A6: বল | B6: 5
A7: রে | B7: 5
A8: দেব | B8: 4
A9: মন | B9: 4
A10: আলো | B10: 3
A11: গো | B11: 3
A12: চড় | B12: 3
... A270: হোথা | B270: 1
A271: 0 | B271: 0
B272: 0

Sheet ending_ends
A1: আ | B1: {=_xlfn.UNIQUE(A:A,FALSE,FALSE)} -> আ | C1: =COUNTIF(A:A,B1) -> 20
A2: আ | B2: আ | C2: =COUNTIF(A:A,B2) -> 1
A3: আ | B3: ই | C3: =COUNTIF(A:A,B3) -> 33
A4: আ | B4: ই | C4: =COUNTIF(A:A,B4) -> 1
A5: আ | B5: এ | C5: =COUNTIF(A:A,B5) -> 84
A6: আ | B6: ও | C6: =COUNTIF(A:A,B6) -> 2
A7: আ | B7: কি | C7: =COUNTIF(A:A,B7) -> 1
A8: আ | B8: গো | C8: =COUNTIF(A:A,B8) -> 1
A9: আ | B9: ছি | C9: =COUNTIF(A:A,B9) -> 8
A10: আ | B10: ছিনু | C10: =COUNTIF(A:A,B10) -> 2
A11: আ | B11: ছে | C11: =COUNTIF(A:A,B11) -> 10
A12: আ | B12: ছো | C12: =COUNTIF(A:A,B12) -> 6
A13: আ | B13: টি | C13: =COUNTIF(A:A,B13) -> 2
... A27: ই | B27: বো | C27: =COUNTIF(A:A,B27) -> 1
A28: ই | B28: 0 | C28: =COUNTIF(A:A,B28) -> 0
A29: ই | C29: =COUNTIF(A:A,B29) -> 0
A30: ই | C30: =COUNTIF(A:A,B30) -> 0
A31: ই | C31: =COUNTIF(A:A,B31) -> 0
A32: ই | C32: =COUNTIF(A:A,B32) -> 0
A33: ই | C33: =COUNTIF(A:A,B33) -> 0
A34: ই | C34: =COUNTIF(A:A,B34) -> 0
A35: ই | C35: =COUNTIF(A:A,B35) -> 0
A36: ই | C36: =COUNTIF(A:A,B36) -> 0
A37: ই
A38: ই
A39: ই
A40: ই
A41: ই
A42: ই
A43: ই
A44: ই
A45: ই
A46: ই
A47: ই
A48: ই
... A214: বো

Sheet Sheet6
A1: এ | B1: 84 | C1: 4
A2: ই | B2: 33 | C2: 4
A3: আ | B3: 20 | C3: 4
A4: ছে | B4: 10 | C4: 4
A5: ছি | B5: 8 | C5: 4
A6: য় | B6: 7 | C6: 2
A7: লো | B7: 7 | C7: 2
A8: ছো | B8: 6 | C8: 2
A9: তে | B9: 6 | C9: 2
A10: বে | B10: 4 | C10: 2
A11: র | B11: 3 | C11: 2
A12: লে | B12: 3 | C12: 2
... A25: সে | B25: 1 | C25: 2

Sheet UniqueCount
A1: ই | B1: 8
A2: এ | B2: 8
A3: যে | B3: 7
A4: আম | B4: 7
A5: যা | B5: 4
A6: কর | B6: 4
A7: বল | B7: 4
A8: এক | B8: 4
A9: আ | B9: 4
A10: আ | B10: 4
A11: উ | B11: 4
A12: ও | B12: 4
... A70: উঠ | B70: 2
A71: তুমি | B71: 2 | F71: =SUM(B:B) -> 423
A72: সকাল | B72: 2
A73: হাত | B73: 2
A74: না | B74: 1
A75: যা | B75: 1
A76: চল | B76: 1
A77: কর | B77: 1
A78: তার | B78: 1
A79: বল | B79: 1
A80: রে | B80: 1
A81: দেব | B81: 1
A82: মন | B82: 1
A83: আলো | B83: 1
... A226: হত | B226: 1

Sheet Sheet10
A1: না | B1: ভাল | C1: আগ | D1: বার | E1: কে | F1: ই | G1: ই | H1: ই | I1: ই | J1: ই | K1: বায় | L1: আজ | M1: কাবার | N1: পাখি | O1: খোকা | P1: সময় | Q1: উ | R1: গেছ | S1: জানালা | T1: তৈরি | U1: নুন | V1: বাউল | W1: মাঝি | X1: শিব
A2: যা | B2: ভালো | C2: আপন | D2: এস | E2: কো | F2: এ | G2: এ | H2: এ | I2: এ | J2: এ | K2: বুঝ | L2: আড় | M2: কামড় | N2: বাজ | O2: গাছ | P2: সাগর | Q2: এ | R2: গেলেম | S2: জান | T2: থরথরি | U2: নেংটিইঁদুর | V2: বাগ | W2: মাথাভরা | X2: শিমূল
A3: চল | B3: মোর | C3: আয় | D3: কই | E3: গো | F3: যে | G3: যে | H3: যে | I3: যে | J3: যে | K3: বৃষ্টি | L3: আদেশ | M3: কার্তিক | N3: বাস | O3: ছেলে | P3: হব | Q3: ও | R3: গোঁফ | S3: জাল | T3: থানা | U3: নোখ | V3: বাজনা | W3: মালা | X3: শিশু
A4: কর | B4: না | C4: উড় | D4: কাঁপ | E4: ছি | F4: আম | G4: আম | H4: আম | I4: আম | J4: আম | K4: বোন | L4: আমাশয় | M4: কাল | N4: বুন | O4: পর | P4: অন্ধকার | Q4: কি | R4: গোণ | S4: জিরোয় | T4: থাপড় | U4: নৌকাজাহাজ | V4: বাট | W4: মাসি | X4: শুল
A5: তার | B5: যা | C5: কথা | D5: কাট | E5: ছিনু | F5: যা | G5: যা | H5: যা | I5: যা | J5: ই | K5: বোল | L5: আলসে | M5: কালো | N5: বেশ | O5: নদী | P5: আবার | Q5: কি | R5: গোবিন | S5: জিলিপি | T5: দগ্ধ | U5: পঁচা | V5: বাতাস | W5: মিল | X5: শেষ
A6: বল | B6: কর | C6: ঘর | D6: কী | E6: ছে | F6: কর | G6: কর | H6: কর | I6: কর | J6: এ | K6: ভর | L6: আলোর | M6: কালো | N6: ভাই | O6: মো | P6: খান | Q6: কু | R6: গোরা | S6: জুড়িদার | T6: দরজা | U6: পথ | V6: বাপু | W6: মুদ | X6: শোভিত
A7: রে | B7: বল | C7: ঘোড়া | D7: কেটে | E7: ছো | F7: বল | G7: বল | H7: বল | I7: বল | J7: যে | K7: ভেসে | L7: আশা | M7: কাষ্ঠ | N7: বল | O7: লি | P7: লি | Q7: লি | R7: ঘট | S7: জেগে | T7: দলবল | U7: পরহিত | V7: বাপ | W7: মেখে | X7: শ্যাম
A8: দেব | B8: তার | C8: ঝক | D8: খোকন | E8: টা | F8: এক | G8: এক | H8: এক | I8: এক | J8: আম | K8: ভোদড় | L8: আষাঢ় | M8: কাস্তে | N8: এক | O8: লে | P8: লে | Q8: লে | R8: ঘাড় | S8: জোড়াদিঘি | T8: দাঁড়া | U8: পরিষ্কার | V8: বালুচর | W8: মেল | X8: শ্রান্তি
A9: মন | B9: মন | C9: ধান | D9: গেল | E9: টি | F9: আ | G9: আ | H9: আ | I9: আ | J9: ই | K9: ভোর | L9: আসলো | M9: কাহা | N9: আ | O9: লেম | P9: লেম | Q9: লেম | R9: ঘুড়ি | S9: জ্বল | T9: দিই | U9: পরী | V9: বাসা | W9: মোহনা | X9: সকল
A10: আলো | B10: সে | C10: নাম | D10: গোটা | E10: টু | F10: আ | G10: আ | H10: আ | I10: আ | J10: এ | K10: মন্ত্র | L10: আস্ত | M10: কাহিনী | N10: আ | O10: লো | P10: লো | Q10: লো | R10: জাগা | S10: জ্যান্ত | T10: দিকপান | U10: পাঁচিল | V10: বাসাখানি | W10: মোহিত | X10: সঞ্চয়
A11: গো | B11: আর | C11: পাখ | D11: চোখ | E11: তে | F11: উ | G11: উ | H11: উ | I11: উ | J11: যে | K11: মাঝ | L11: আহরণ | M11: কিচিমিচি | N11: উ | O11: সে | P11: সে | Q11: সে | R11: ভাঙা | S11: ঝগড়া | T11: দিঘি | U11: পাই | V11: বাস্ | W11: মৌন | X11: সড়াৎ
A12: চড় | B12: আস | C12: পান | D12: মেয়ে | E12: তো | F12: ও | G12: ও | H12: ও | I12: ও | J12: আম | K12: মাটি | L12: ইঙ্গিত | M12: কিশোর | N12: ও | O12: ইস | P12: ইস | Q12: ইস | R12: ঘুসি | S12: ঝরনা | T12: দিদি | U12: পাকা | V12: বিদেশ | W12: ম্যালেরিয়া | X12: সন
... A40: নাচ | B40: আছ | C40: রাত | D40: আ | E40: যা | F40: রে | G40: রে | H40: রে | I40: রে | J40: নি | K40: হাস | L40: কলেরা | M40: গল | N40: বংশী | O40: ভোলা | P40: মাত্র | Q40: হাঁট | R40: ছিপ | S40: তারাদের | T40: নয় | U40: তে | V40: ভাব | W40: সে | X40: না
